Workbook

Sheet Read Me
A1: SFH DEVELOPMENT - QUANTITY TAKEOFF & PRELIMINARY ESTIMATE
A3: Project | B3: SFH Development - single-family spec home (Sidney Aulds Building Studio)
A4: Owner | B4: Chris Hill
A5: Location | B5: Ouachita Parish, Louisiana (address TBD - drawings 'Enter address here')
A6: Building | B6: 1-story, slab-on-grade, 2 bed / 2 bath. 1,352 gsf conditioned + 117 gsf porch + 504 gsf covered parking = 1,973 gsf (design notes)
A7: Estimate purpose / class | B7: Preliminary budget estimate (AACE Class 4-ish, schematic/progress drawings). NOT a bid. Expected accuracy roughly -15% / +25%.
A8: Drawings used | B8: 2305031 Progress Drawings dated 5/31/2023 - G000 (cover), A100, A101, A401, A701 - stamped 'NOT FOR CONSTRUCTION'; Spec Home Schematic Design Notes (3 pp).
A9: Estimate date / price date | B9: 2026-10-15
A10: Units / currency | B10: US customary units (ft, SF, LF, CY, SQ = 100 SF, EA, LS); USD
A11: Pricing basis | B11: Estimator budget unit costs for the Monroe/Ouachita Parish market, Q4-2026. Material costs are pre-tax. These are NOT supplier or subcontractor quotes - replace with local quotes before contracting.
A12: Markups | B12: Sales tax, contingency, overhead and profit are INPUT cells on the Summary sheet (markup on cost). Defaults are placeholders - confirm.
A13: Status | B13: PRELIMINARY - quantities and costs require estimator review. Open RFIs listed on 'Assumptions & RFIs'.
A15: Workflow | B15: Drawing Register -> Takeoff Detail (dims & formulas) -> Cost Database (unit costs w/ source/date) -> Estimate Detail (qty pulled by INDEX/MATCH from takeoff, unit costs from DB) -> Summary (SUMIFS by division + markups) -> Reconciliation (takeoff vs 3D model vs design notes).
... A17: Regenerate | B17: python3 scripts/build_estimate.py then scripts/build_all.sh (recalculates with LibreOffice and rebuilds the model).
A19: COLOR KEY
A20: Blue text / blue fill | B20: Hard-coded input (dimension, count, unit price, markup %) - edit these
A21: Black text | B21: Formula / calculation - do not overwrite
A22: Green text | B22: Link pulled from another sheet
A23: Yellow row fill | B23: Basis = Assumed or Allowance (not measured from drawings)
A24: Orange row fill | B24: Confidence = Low - review before use

Sheet Summary
A1: SFH DEVELOPMENT - PRELIMINARY CONSTRUCTION ESTIMATE
A2: Ouachita Parish, LA | Progress drawings 5/31/2023 (Not for construction) | Price date 2026-10-15 | Budget estimate - not a bid
B4: Conditioned area (gsf, design notes) | C4: 1352 | E4: Sales tax on materials | G4: 0.1 | H4: ASSUMED - verify Ouachita rate for address
B5: Front porch (gsf) | C5: 117 | E5: Contingency (on cost) | G5: 0.05 | H5: placeholder
B6: Covered parking (gsf) | C6: 504 | E6: Overhead (on cost) | G6: 0.08 | H6: placeholder
B7: Total under roof (gsf) | C7: =SUM(C4:C6) -> 1973 | E7: Profit (on cost) | G7: 0.1 | H7: placeholder
A9: Div | B9: Division | C9: Material $ | D9: Labor $ | E9: Sub/Equip $ | F9: Total $ | G9: $ / Cond. SF | H9: % of Direct
A10: 01 | B10: General Requirements | C10: =SUMIFS('Estimate Detail'!$L$2:$L$173,'Estimate Detail'!$B$2:$B$173,$A10) -> 1413.255 | D10: =SUMIFS('Estimate Detail'!$M$2:$M$173,'Estimate Detail'!$B$2:$B$173,$A10) -> 14018.58 | E10: =SUMIFS('Estimate Detail'!$N$2:$N$173,'Estimate Detail'!$B$2:$B$173,$A10) -> 15516.513 | F10: =SUM(C10:E10) -> 30948.347 | G10: =F10/$C$4 -> 22.89079 | H10: =F10/$F$25 -> 0.12104201
A11: 31 | B11: Earthwork | C11: =SUMIFS('Estimate Detail'!$L$2:$L$173,'Estimate Detail'!$B$2:$B$173,$A11) -> 2907 | D11: =SUMIFS('Estimate Detail'!$M$2:$M$173,'Estimate Detail'!$B$2:$B$173,$A11) -> 368 | E11: =SUMIFS('Estimate Detail'!$N$2:$N$173,'Estimate Detail'!$B$2:$B$173,$A11) -> 6305.785 | F11: =SUM(C11:E11) -> 9580.785 | G11: =F11/$C$4 -> 7.0863794 | H11: =F11/$F$25 -> 0.037471386
A12: 03 | B12: Concrete | C12: =SUMIFS('Estimate Detail'!$L$2:$L$173,'Estimate Detail'!$B$2:$B$173,$A12) -> 12009.263 | D12: =SUMIFS('Estimate Detail'!$M$2:$M$173,'Estimate Detail'!$B$2:$B$173,$A12) -> 7346.4397 | E12: =SUMIFS('Estimate Detail'!$N$2:$N$173,'Estimate Detail'!$B$2:$B$173,$A12) -> 5074 | F12: =SUM(C12:E12) -> 24429.703 | G12: =F12/$C$4 -> 18.069307 | H12: =F12/$F$25 -> 0.095546955
A13: 06 | B13: Wood & Rough Carpentry | C13: =SUMIFS('Estimate Detail'!$L$2:$L$173,'Estimate Detail'!$B$2:$B$173,$A13) -> 25289.744 | D13: =SUMIFS('Estimate Detail'!$M$2:$M$173,'Estimate Detail'!$B$2:$B$173,$A13) -> 12125.312 | E13: =SUMIFS('Estimate Detail'!$N$2:$N$173,'Estimate Detail'!$B$2:$B$173,$A13) -> 1150 | F13: =SUM(C13:E13) -> 38565.056 | G13: =F13/$C$4 -> 28.52445 | H13: =F13/$F$25 -> 0.1508317
A14: 07 | B14: Thermal & Moisture Protection | C14: =SUMIFS('Estimate Detail'!$L$2:$L$173,'Estimate Detail'!$B$2:$B$173,$A14) -> 12969.668 | D14: =SUMIFS('Estimate Detail'!$M$2:$M$173,'Estimate Detail'!$B$2:$B$173,$A14) -> 12228.795 | E14: =SUMIFS('Estimate Detail'!$N$2:$N$173,'Estimate Detail'!$B$2:$B$173,$A14) -> 5876.7605 | F14: =SUM(C14:E14) -> 31075.223 | G14: =F14/$C$4 -> 22.984633 | H14: =F14/$F$25 -> 0.12153824
A15: 08 | B15: Openings | C15: =SUMIFS('Estimate Detail'!$L$2:$L$173,'Estimate Detail'!$B$2:$B$173,$A15) -> 10415 | D15: =SUMIFS('Estimate Detail'!$M$2:$M$173,'Estimate Detail'!$B$2:$B$173,$A15) -> 2752 | E15: =SUMIFS('Estimate Detail'!$N$2:$N$173,'Estimate Detail'!$B$2:$B$173,$A15) -> 0 | F15: =SUM(C15:E15) -> 13167 | G15: =F15/$C$4 -> 9.7389053 | H15: =F15/$F$25 -> 0.051497424
A16: 09 | B16: Finishes | C16: =SUMIFS('Estimate Detail'!$L$2:$L$173,'Estimate Detail'!$B$2:$B$173,$A16) -> 7388.183 | D16: =SUMIFS('Estimate Detail'!$M$2:$M$173,'Estimate Detail'!$B$2:$B$173,$A16) -> 18569.468 | E16: =SUMIFS('Estimate Detail'!$N$2:$N$173,'Estimate Detail'!$B$2:$B$173,$A16) -> 0 | F16: =SUM(C16:E16) -> 25957.651 | G16: =F16/$C$4 -> 19.199446 | H16: =F16/$F$25 -> 0.10152291
A17: 10 | B17: Specialties | C17: =SUMIFS('Estimate Detail'!$L$2:$L$173,'Estimate Detail'!$B$2:$B$173,$A17) -> 993 | D17: =SUMIFS('Estimate Detail'!$M$2:$M$173,'Estimate Detail'!$B$2:$B$173,$A17) -> 599 | E17: =SUMIFS('Estimate Detail'!$N$2:$N$173,'Estimate Detail'!$B$2:$B$173,$A17) -> 0 | F17: =SUM(C17:E17) -> 1592 | G17: =F17/$C$4 -> 1.1775148 | H17: =F17/$F$25 -> 0.0062264676
A18: 11 | B18: Equipment (Appliances) | C18: =SUMIFS('Estimate Detail'!$L$2:$L$173,'Estimate Detail'!$B$2:$B$173,$A18) -> 85 | D18: =SUMIFS('Estimate Detail'!$M$2:$M$173,'Estimate Detail'!$B$2:$B$173,$A18) -> 350 | E18: =SUMIFS('Estimate Detail'!$N$2:$N$173,'Estimate Detail'!$B$2:$B$173,$A18) -> 0 | F18: =SUM(C18:E18) -> 435 | G18: =F18/$C$4 -> 0.32174556 | H18: =F18/$F$25 -> 0.0017013275
A19: 12 | B19: Casework & Countertops | C19: =SUMIFS('Estimate Detail'!$L$2:$L$173,'Estimate Detail'!$B$2:$B$173,$A19) -> 8669.14 | D19: =SUMIFS('Estimate Detail'!$M$2:$M$173,'Estimate Detail'!$B$2:$B$173,$A19) -> 1776.5 | E19: =SUMIFS('Estimate Detail'!$N$2:$N$173,'Estimate Detail'!$B$2:$B$173,$A19) -> 0 | F19: =SUM(C19:E19) -> 10445.64 | G19: =F19/$C$4 -> 7.7260651 | H19: =F19/$F$25 -> 0.040853919
A20: 22 | B20: Plumbing | C20: =SUMIFS('Estimate Detail'!$L$2:$L$173,'Estimate Detail'!$B$2:$B$173,$A20) -> 7150 | D20: =SUMIFS('Estimate Detail'!$M$2:$M$173,'Estimate Detail'!$B$2:$B$173,$A20) -> 8355 | E20: =SUMIFS('Estimate Detail'!$N$2:$N$173,'Estimate Detail'!$B$2:$B$173,$A20) -> 275 | F20: =SUM(C20:E20) -> 15780 | G20: =F20/$C$4 -> 11.671598 | H20: =F20/$F$25 -> 0.061717122
A21: 23 | B21: HVAC | C21: =SUMIFS('Estimate Detail'!$L$2:$L$173,'Estimate Detail'!$B$2:$B$173,$A21) -> 7429.125 | D21: =SUMIFS('Estimate Detail'!$M$2:$M$173,'Estimate Detail'!$B$2:$B$173,$A21) -> 4567.25 | E21: =SUMIFS('Estimate Detail'!$N$2:$N$173,'Estimate Detail'!$B$2:$B$173,$A21) -> 175 | F21: =SUM(C21:E21) -> 12171.375 | G21: =F21/$C$4 -> 9.0024963 | H21: =F21/$F$25 -> 0.047603437
... A24: 33 | B24: Utilities | C24: =SUMIFS('Estimate Detail'!$L$2:$L$173,'Estimate Detail'!$B$2:$B$173,$A24) -> 0 | D24: =SUMIFS('Estimate Detail'!$M$2:$M$173,'Estimate Detail'!$B$2:$B$173,$A24) -> 0 | E24: =SUMIFS('Estimate Detail'!$N$2:$N$173,'Estimate Detail'!$B$2:$B$173,$A24) -> 7190 | F24: =SUM(C24:E24) -> 7190 | G24: =F24/$C$4 -> 5.3180473 | H24: =F24/$F$25 -> 0.028120793
B25: TOTAL DIRECT COST | C25: =SUM(C10:C24) -> 112469.36 | D25: =SUM(D10:D24) -> 100225.28 | E25: =SUM(E10:E24) -> 42988.058 | F25: =SUM(F10:F24) -> 255682.69 | G25: =F25/$C$4 -> 189.11442 | H25: =F25/F25 -> 1
B26: Sales tax on materials | F26: =C25*G4 -> 11246.936 | G26: =F26/$C$4 -> 8.3187395
B27: Subtotal with tax | F27: =F25+F26 -> 266929.63 | G27: =F27/$C$4 -> 197.43316
B28: Contingency | F28: =F27*G5 -> 13346.481 | G28: =F28/$C$4 -> 9.8716579
B29: Overhead | F29: =(F27+F28)*G6 -> 22422.089 | G29: =F29/$C$4 -> 16.584385
B30: Profit | F30: =(F27+F28+F29)*G7 -> 30269.82 | G30: =F30/$C$4 -> 22.38892
B31: GRAND TOTAL (budget) | F31: =F27+F28+F29+F30 -> 332968.02 | G31: =F31/$C$4 -> 246.27812
B32: Grand total per SF under roof (1,973 gsf) | F32: =F31/C7 -> 168.7623
B34: Excluded: land, financing & closing, sales commissions, appliances & W/D (owner), window coverings, fencing, irrigation, septic, gas service, security/AV, solar, architect fees, builder's warranty reserve, escalation beyond price date, rock/unsuitable soil removal, flood elevation above 12" pad.

Sheet Drawing Register
A1: Sheet | B1: Title | C1: Discipline | D1: Scale | E1: Revision / Date | F1: Status | G1: File / Page | H1: Used for | I1: Notes / Issues
A2: G000 | B2: Cover sheet (rendering, project team) | C2: General | D2: NTS | E2: Progress 5/31/2023 | F2: Not for construction | G2: 2305031_Progress_Drawings.pdf p1 | H2: Massing check (rendering) | I2: No sheet number printed on page; design notes call it G000. Project team blank (no structural/MEP engineers).
A3: A100 | B3: Site plan | C3: Architectural | D3: 1/16" = 1'-0" | E3: Progress 5/31/2023 | F3: Not for construction | G3: p2 | H3: Lot 50' x 180', setbacks, driveway | I3: Design notes list 'A100 - Plans'; set has A100 = Site Plan, A101 = Plans (numbering conflict, RFI-16). Address 'Enter address here'.
A4: A101 | B4: Plans: finish floor, finish floor RCP, T.O. plate (roof) | C4: Architectural | D4: 1/8" = 1'-0" | E4: Progress 5/31/2023 | F4: Not for construction | G4: p3 | H4: Primary takeoff: overall dims 21'-0" x 70'-0" + 24'-0" carport, room chain, partitions, RCP ceiling heights & fixtures | I4: Calibrated: 21'-0" = 395 px @150 dpi (18.81 px/ft); vertical chain 70'-0" = 1,312 px (18.74 px/ft) - 0.4% check. Interior partitions not dimensioned (SCALED).
A5: A401 | B5: Building elevations A-D | C5: Architectural | D5: 1/4" = 1'-0" | E5: Progress 5/31/2023 | F5: Not for construction | G5: p4 | H5: T.O. plate 9'-0", 6/12 pitch, cladding types, window/door tags, gutters | I5: Overhangs not dimensioned (ASSUMED 12").
A6: A701 | B6: Schedules & details (door/window schedules, types) | C6: Architectural | D6: NTS | E6: Progress 5/31/2023 | F6: Not for construction | G6: p5 | H6: Door & window counts/sizes | I6: Door 01 R1 4'-0" x 8'-0" leaf/sidelite split not dimensioned.
A7: Notes | B7: Spec Home Schematic Design Notes | C7: Narrative spec | D7: — | E7: Undated | F7: Schematic | G7: Spec_Home_Schematic_Design_Notes.pdf (3 pp) | H7: Finishes, framing, sheathing, HVAC, areas | I7: Areas: porch 117, conditioned 1,352, covered parking 504, total 1,973 gsf.
A8: — | B8: Structural drawings | C8: Structural | D8: — | E8: MISSING | F8: Not issued | G8: — | H8: — | I8: Foundation, beams, trusses: ASSUMED. RFI-05.
A9: — | B9: MEP drawings | C9: MEP | D9: — | E9: MISSING | F9: Not issued | G9: — | H9: — | I9: HVAC, electrical, plumbing priced as design-build allowances.

Sheet Assumptions & RFIs
A1: ID | B1: Category | C1: Question / Issue | D1: Assumption used in this estimate | E1: Qty / cost impact | F1: Responsible | G1: Status | H1: Resolution
A2: RFI-01 | B2: Site | C2: Property address, survey, topography, flood zone, utility locations and street type (curb vs. open ditch) are not provided ('Enter address here'). | D2: Typical in-town Ouachita Parish lot 50' x 180' per A100, lightly treed, public water & sewer at the street, open-ditch possible. | E2: 31-100 clearing, 32-130 culvert, 33-1xx utilities are allowances (~$13k combined). | F2: Owner | G2: Open
A3: RFI-02 | B3: Permits | C3: Permitting jurisdiction (City of Monroe, City of West Monroe, or unincorporated Ouachita Parish) and fee schedule. | D3: Permit & plan review allowance $2,600 plus trade permits. | E3: 01-100, 22-195, 23-160, 26-350 | F3: Owner/GC | G3: Open
A4: RFI-03 | B4: Energy code | C4: Insulation R-values, fenestration U-factor/SHGC and testing requirements are not specified. | D4: R-21 walls, R-38 ceiling, standard Low-E vinyl windows, blower-door/duct test allowance. | E4: 07-100/110, 01-210 | F4: Architect | G4: Assumed
A5: RFI-04 | B5: Geotechnical | C5: No soils report. NE Louisiana clays are often expansive; slab design and pad height depend on PI and flood elevation. | D5: 12" average select-fill pad, 5' beyond slab, conventional reinforced monolithic slab. Geotech allowance carried. | E5: 31-120 (149 CY loose), 03-1xx, 01-106. A post-tensioned or stiffened slab could change foundation cost +/- $4-8k. | F5: Owner/Engineer | G5: Open
A6: RFI-05 | B6: Structural | C6: No structural drawings (project team lists none). Foundation, beam, header and connector design are by others. | D6: 4" slab, 12"x24" perimeter beam (4 #5), 12"x20" interior beams on ~20' grid, #3 @ 18" EW, (2) 2x10 headers. | E6: 03-100..150, 06-130 | F6: Engineer | G6: Open
A7: RFI-06 | B7: Roof framing | C7: Design notes call for 'cambered roof truss 4' O.C.' with ZIP roof sheathing. ZIP roof panels are typically span-rated for 24" supports, and 5/8" gypsum ceilings need supports at 24" max. | D7: Trusses at 48" O.C. as noted PLUS 2x4 roof purlins @ 24" and 2x4 ceiling furring @ 24". Alternative: trusses @ 24" O.C. (~+21 trusses, -purlins/furring). | E7: 06-190..220. Purlins + furring ~ $2.0k material + labor in framing rate. | F7: Architect/Truss mfr. | G7: Open
A8: RFI-07 | B8: Structural | C8: Covered parking has posts only at the two rear corners (A101/A401): 24' clear-span eave beams required. Open porch front also needs a ~21' beam. | D8: 3-1/2" x 14" LVL (2-ply) both carport eaves and porch front; 6x6 PT posts on 24" footings. | E8: 06-250 (72 LF), 06-260, 03-220 | F8: Engineer | G8: Open
A9: RFI-08 | B9: Roof geometry | C9: Eave and rake overhangs are not dimensioned. A401 scales to roughly 8-12". | D9: 12" eave and 12" rake overhang on all sides; boxed, vented FC soffit. | E9: Roof area, fascia, soffit, gutters (each +/-3%). | F9: Architect | G9: Assumed
A10: RFI-09 | B10: Cladding | C10: Design notes conflict: 'lap siding front porch' vs 'Fiber Cement Tongue & Groove Siding (continued to ceiling)'. A401 Elev B says 'Fiber cement T&G siding'. | D10: Fiber cement T&G (per A401) at porch walls, front gable and porch ceiling. | E10: 07-160/170 (~$3.0k). | F10: Architect | G10: Open
A11: RFI-10 | B11: Code/egress | C11: Bedroom egress: Type B 6'-0" x 4'-0" casement at 3'-0" sill. Confirm clear opening/sill height meet egress. | D11: Type B casement as scheduled (twin casement). | E11: None if compliant. | F11: Architect | G11: Open
A12: RFI-11 | B12: Code/glazing | C12: Type D windows adjacent to door 01 and the door 01 sidelite may require safety glazing. | D12: Door 01 sidelite tempered (in door price); D windows standard glass. | E12: Tempered D windows ~+$150 ea. | F12: Architect | G12: Open
A13: RFI-12 | B13: Doors | C13: Door 01 (R1) is scheduled 4'-0" x 8'-0" but leaf vs. sidelite split is not dimensioned (A701 shows 4'-0" and 2'-0" marks). Door material not specified (frame wood). | D13: 3'-0" x 8'-0" leaf + 1'-0" sidelite, prehung, fiberglass or wood. | E13: 08-200 | F13: Architect | G13: Open
... A23: RFI-22 | B23: Exterior paint | C23: Fiber cement finish: factory-primed vs. pre-finished (e.g., ColorPlus) not specified. | D23: Primed product, field painted (09-260/265). | E23: Pre-finished could save ~$3-4k paint, add ~$1.5k material. | F23: Owner | G23: Assumed
A24: A-01 | B24: Wall heights | C24: All walls framed to 9'-0" T.O. plate (A401). Rooms with 8'-0" ceilings get dropped ceiling joists. | D24: 104-5/8" precut studs, 9' drywall walls everywhere (slight over-measure in 8' rooms). | F24: Estimator | G24: Assumed
A25: A-02 | B25: Openings | C25: Opening deductions: siding and drywall deduct actual window/door areas; sheathing does not (cut waste). Waste factors applied separately per line. | F25: Estimator | G25: Assumed
A26: A-03 | B26: Pricing | C26: Unit costs are estimator budget values for the Monroe/Ouachita market at 2026-10-15, pre-tax materials, open-shop labor. Not quotes. | D26: Sales tax 10% on materials placeholder; contingency 5%, overhead 8%, profit 10% (on cost) placeholders. | E26: Summary inputs. | F26: Owner/GC | G26: Assumed
A27: A-04 | B27: Schedule | C27: Construction duration ~5 months (20 weeks) for general conditions. | E27: 01-130/140/160 | F27: GC | G27: Assumed
A28: A-05 | B28: Owner items | C28: Appliances (range, refrigerator, OTR microwave, dishwasher) and washer/dryer supplied by owner per design notes; contractor installs/hooks up. | E28: 11-100 = $0; 11-110 hookup allowance. | F28: Owner | G28: Assumed

Sheet Takeoff Detail
A1: ID | B1: Cost Code | C1: Division | D1: Description | E1: Spec / Reference | F1: Sheet | G1: Location | H1: Takeoff Type | I1: Count | J1: Length (ft) | K1: Width / Ht (ft) | L1: Depth (ft) | M1: Factor | N1: Deduct | O1: Net Qty | P1: Unit | Q1: Waste % | R1: Gross Qty | S1: Round Up? | T1: Calculation / Method | U1: Basis | V1: Confidence | W1: Notes / Assumptions
A2: 01-100 | B2: 01 | C2: General Requirements | D2: Building permit & plan review | E2: Ouachita Parish / municipal residential permit | F2: — | G2: Project | H2: Allowance | I2: 1 | O2: =IF(I2="",1,I2)*IF(J2="",1,J2)*IF(K2="",1,K2)*IF(L2="",1,L2)*IF(M2="",1,M2)-N(N2) -> 1 | P2: LS | Q2: 0 | R2: =IF(S2="Y",ROUNDUP(O2*(1+Q2),0),O2*(1+Q2)) -> 1 | S2: N | U2: Allowance | V2: Medium | W2: Jurisdiction depends on final address (City of Monroe, West Monroe or unincorporated Ouachita). RFI-02.
A3: 01-105 | B3: 01 | C3: General Requirements | D3: Engineering: foundation design, carport/porch beams, truss review | E3: Licensed LA engineer letter/stamp | F3: — | G3: Project | H3: Allowance | I3: 1 | O3: =IF(I3="",1,I3)*IF(J3="",1,J3)*IF(K3="",1,K3)*IF(L3="",1,L3)*IF(M3="",1,M3)-N(N3) -> 1 | P3: LS | Q3: 0 | R3: =IF(S3="Y",ROUNDUP(O3*(1+Q3),0),O3*(1+Q3)) -> 1 | S3: N | U3: Allowance | V3: Medium | W3: No structural drawings in set. RFI-05/06/07.
A4: 01-106 | B4: 01 | C4: General Requirements | D4: Geotechnical investigation (borings, PI, slab recommendations) | E4: Recommended for NE LA expansive clays | F4: — | G4: Site | H4: Allowance | I4: 1 | O4: =IF(I4="",1,I4)*IF(J4="",1,J4)*IF(K4="",1,K4)*IF(L4="",1,L4)*IF(M4="",1,M4)-N(N4) -> 1 | P4: LS | Q4: 0 | R4: =IF(S4="Y",ROUNDUP(O4*(1+Q4),0),O4*(1+Q4)) -> 1 | S4: N | U4: Allowance | V4: Medium | W4: RFI-04
A5: 01-110 | B5: 01 | C5: General Requirements | D5: Survey: boundary, staking, form-board, final as-built | F5: A100 | G5: Site | H5: Allowance | I5: 1 | O5: =IF(I5="",1,I5)*IF(J5="",1,J5)*IF(K5="",1,K5)*IF(L5="",1,L5)*IF(M5="",1,M5)-N(N5) -> 1 | P5: LS | Q5: 0 | R5: =IF(S5="Y",ROUNDUP(O5*(1+Q5),0),O5*(1+Q5)) -> 1 | S5: N | U5: Allowance | V5: Medium
A6: 01-120 | B6: 01 | C6: General Requirements | D6: Temporary power pole, connection & usage | F6: — | G6: Site | H6: Allowance | I6: 1 | O6: =IF(I6="",1,I6)*IF(J6="",1,J6)*IF(K6="",1,K6)*IF(L6="",1,L6)*IF(M6="",1,M6)-N(N6) -> 1 | P6: LS | Q6: 0 | R6: =IF(S6="Y",ROUNDUP(O6*(1+Q6),0),O6*(1+Q6)) -> 1 | S6: N | U6: Allowance | V6: Medium
A7: 01-125 | B7: 01 | C7: General Requirements | D7: Temporary water & usage | F7: — | G7: Site | H7: Allowance | I7: 1 | O7: =IF(I7="",1,I7)*IF(J7="",1,J7)*IF(K7="",1,K7)*IF(L7="",1,L7)*IF(M7="",1,M7)-N(N7) -> 1 | P7: LS | Q7: 0 | R7: =IF(S7="Y",ROUNDUP(O7*(1+Q7),0),O7*(1+Q7)) -> 1 | S7: N | U7: Allowance | V7: Medium
A8: 01-130 | B8: 01 | C8: General Requirements | D8: Portable toilet | F8: — | G8: Site | H8: Count | I8: 5 | O8: =IF(I8="",1,I8)*IF(J8="",1,J8)*IF(K8="",1,K8)*IF(L8="",1,L8)*IF(M8="",1,M8)-N(N8) -> 5 | P8: MO | Q8: 0 | R8: =IF(S8="Y",ROUNDUP(O8*(1+Q8),0),O8*(1+Q8)) -> 5 | S8: N | T8: 5 month schedule | U8: Assumed | V8: Medium | W8: Schedule ASSUMED 5 months.
A9: 01-140 | B9: 01 | C9: General Requirements | D9: Dumpster, 20 CY, haul & dump | F9: — | G9: Site | H9: Count | I9: 5 | O9: =IF(I9="",1,I9)*IF(J9="",1,J9)*IF(K9="",1,K9)*IF(L9="",1,L9)*IF(M9="",1,M9)-N(N9) -> 5 | P9: EA | Q9: 0 | R9: =IF(S9="Y",ROUNDUP(O9*(1+Q9),0),O9*(1+Q9)) -> 5 | S9: N | T9: ~1 pull per month | U9: Assumed | V9: Medium
A10: 01-150 | B10: 01 | C10: General Requirements | D10: Builder's risk insurance | F10: — | G10: Project | H10: Allowance | I10: 1 | O10: =IF(I10="",1,I10)*IF(J10="",1,J10)*IF(K10="",1,K10)*IF(L10="",1,L10)*IF(M10="",1,M10)-N(N10) -> 1 | P10: LS | Q10: 0 | R10: =IF(S10="Y",ROUNDUP(O10*(1+Q10),0),O10*(1+Q10)) -> 1 | S10: N | U10: Allowance | V10: Medium
A11: 01-160 | B11: 01 | C11: General Requirements | D11: Site supervision (part-time superintendent) | F11: — | G11: Project | H11: Count | I11: 20 | O11: =IF(I11="",1,I11)*IF(J11="",1,J11)*IF(K11="",1,K11)*IF(L11="",1,L11)*IF(M11="",1,M11)-N(N11) -> 20 | P11: WK | Q11: 0 | R11: =IF(S11="Y",ROUNDUP(O11*(1+Q11),0),O11*(1+Q11)) -> 20 | S11: N | T11: 20 weeks x part-time super | U11: Assumed | V11: Medium
A12: 01-170 | B12: 01 | C12: General Requirements | D12: Final construction clean incl. windows | F12: A101 | G12: All areas | H12: Area | I12: 1 | J12: 21 | K12: 94.083333 | O12: =IF(I12="",1,I12)*IF(J12="",1,J12)*IF(K12="",1,K12)*IF(L12="",1,L12)*IF(M12="",1,M12)-N(N12) -> 1975.75 | P12: SF | Q12: 0 | R12: =IF(S12="Y",ROUNDUP(O12*(1+Q12),0),O12*(1+Q12)) -> 1975.75 | S12: N | T12: 21' x 94.08' under roof | U12: Calculated | V12: High
A13: 01-175 | B13: 01 | C13: General Requirements | D13: Periodic jobsite cleanup | F13: — | G13: Project | H13: Allowance | I13: 1 | O13: =IF(I13="",1,I13)*IF(J13="",1,J13)*IF(K13="",1,K13)*IF(L13="",1,L13)*IF(M13="",1,M13)-N(N13) -> 1 | P13: LS | Q13: 0 | R13: =IF(S13="Y",ROUNDUP(O13*(1+Q13),0),O13*(1+Q13)) -> 1 | S13: N | U13: Allowance | V13: Medium
A14: 01-180 | B14: 01 | C14: General Requirements | D14: Finished-slab protection (Ram Board/taped) - smooth trowel floors | E14: Design notes: concrete floors are the finish | F14: Notes | G14: Conditioned | H14: Area | J14: 21 | K14: 64.166667 | O14: =IF(I14="",1,I14)*IF(J14="",1,J14)*IF(K14="",1,K14)*IF(L14="",1,L14)*IF(M14="",1,M14)-N(N14) -> 1347.5 | P14: SF | Q14: 0.1 | R14: =IF(S14="Y",ROUNDUP(O14*(1+Q14),0),O14*(1+Q14)) -> 1482.25 | S14: N | T14: 21' x 64.17' | U14: Calculated | V14: High | W14: Required because finished floor is exposed concrete.
A15: 01-190 | B15: 01 | C15: General Requirements | D15: Termite pre-treatment & LDAF certificate | E15: Louisiana pre-construction termite treatment | F15: — | G15: Slab | H15: Allowance | I15: 1 | O15: =IF(I15="",1,I15)*IF(J15="",1,J15)*IF(K15="",1,K15)*IF(L15="",1,L15)*IF(M15="",1,M15)-N(N15) -> 1 | P15: LS | Q15: 0 | R15: =IF(S15="Y",ROUNDUP(O15*(1+Q15),0),O15*(1+Q15)) -> 1 | S15: N | U15: Allowance | V15: Medium
A16: 01-200 | B16: 01 | C16: General Requirements | D16: Small tools & consumables | F16: — | G16: Project | H16: Allowance | I16: 1 | O16: =IF(I16="",1,I16)*IF(J16="",1,J16)*IF(K16="",1,K16)*IF(L16="",1,L16)*IF(M16="",1,M16)-N(N16) -> 1 | P16: LS | Q16: 0 | R16: =IF(S16="Y",ROUNDUP(O16*(1+Q16),0),O16*(1+Q16)) -> 1 | S16: N | U16: Allowance | V16: Medium
A17: 01-210 | B17: 01 | C17: General Requirements | D17: Energy code testing (blower door / duct leakage) | F17: — | G17: Project | H17: Allowance | I17: 1 | O17: =IF(I17="",1,I17)*IF(J17="",1,J17)*IF(K17="",1,K17)*IF(L17="",1,L17)*IF(M17="",1,M17)-N(N17) -> 1 | P17: LS | Q17: 0 | R17: =IF(S17="Y",ROUNDUP(O17*(1+Q17),0),O17*(1+Q17)) -> 1 | S17: N | U17: Allowance | V17: Medium | W17: Verify requirement with AHJ (RFI-03).
A18: 31-100 | B18: 31 | C18: Earthwork | D18: Clear & grub, strip topsoil (building & drive area) | F18: A100 | G18: Site | H18: Allowance | I18: 1 | O18: =IF(I18="",1,I18)*IF(J18="",1,J18)*IF(K18="",1,K18)*IF(L18="",1,L18)*IF(M18="",1,M18)-N(N18) -> 1 | P18: LS | Q18: 0 | R18: =IF(S18="Y",ROUNDUP(O18*(1+Q18),0),O18*(1+Q18)) -> 1 | S18: N | U18: Allowance | V18: Low | W18: Lot condition unknown (address TBD). RFI-01.
A19: 31-120 | B19: 31 | C19: Earthwork | D19: Select fill building pad, 12" avg, compacted (loose CY incl. 25% shrink) | E19: Slab footprint + 5' each side | F19: A101 | G19: Building pad | H19: Volume | J19: 31 | K19: 104.08333 | L19: 1 | M19: 0.037037037 | O19: =IF(I19="",1,I19)*IF(J19="",1,J19)*IF(K19="",1,K19)*IF(L19="",1,L19)*IF(M19="",1,M19)-N(N19) -> 119.50309 | P19: CY | Q19: 0.25 | R19: =IF(S19="Y",ROUNDUP(O19*(1+Q19),0),O19*(1+Q19)) -> 150 | S19: Y | T19: (21+10) x (94.08+10) x 1.0' / 27 | U19: Assumed | V19: Low | W19: Pad height ASSUMED 12" avg; set by survey/geotech & flood zone. RFI-04.
A20: 31-130 | B20: 31 | C20: Earthwork | D20: Fine grade building pad | F20: A101 | G20: Building pad | H20: Area | J20: 31 | K20: 104.08333 | O20: =IF(I20="",1,I20)*IF(J20="",1,J20)*IF(K20="",1,K20)*IF(L20="",1,L20)*IF(M20="",1,M20)-N(N20) -> 3226.5833 | P20: SF | Q20: 0 | R20: =IF(S20="Y",ROUNDUP(O20*(1+Q20),0),O20*(1+Q20)) -> 3226.5833 | S20: N | T20: 31' x 104.08' | U20: Calculated | V20: High
A21: 31-140 | B21: 31 | C21: Earthwork | D21: Final grading & topsoil spread | F21: A100 | G21: Lot | H21: Allowance | I21: 1 | O21: =IF(I21="",1,I21)*IF(J21="",1,J21)*IF(K21="",1,K21)*IF(L21="",1,L21)*IF(M21="",1,M21)-N(N21) -> 1 | P21: LS | Q21: 0 | R21: =IF(S21="Y",ROUNDUP(O21*(1+Q21),0),O21*(1+Q21)) -> 1 | S21: N | U21: Allowance | V21: Medium
A22: 31-150 | B22: 31 | C22: Earthwork | D22: Silt fence / erosion control | F22: A100 | G22: Lot perimeter (front & sides) | H22: Length | J22: 230 | O22: =IF(I22="",1,I22)*IF(J22="",1,J22)*IF(K22="",1,K22)*IF(L22="",1,L22)*IF(M22="",1,M22)-N(N22) -> 230 | P22: LF | Q22: 0 | R22: =IF(S22="Y",ROUNDUP(O22*(1+Q22),0),O22*(1+Q22)) -> 230 | S22: N | T22: front 50' + 2 sides x 90' | U22: Assumed | V22: Medium
A23: 03-100 | B23: 03 | C23: Concrete | D23: Slab-on-grade 4" (house, porch, carport) - concrete | E23: 3000 psi ready-mix | F23: A101 | G23: Footprint 21' x 94.08' | H23: Volume | J23: 21 | K23: 94.083333 | L23: 0.33333333 | M23: 0.037037037 | O23: =IF(I23="",1,I23)*IF(J23="",1,J23)*IF(K23="",1,K23)*IF(L23="",1,L23)*IF(M23="",1,M23)-N(N23) -> 24.391975 | P23: CY | Q23: 0.05 | R23: =IF(S23="Y",ROUNDUP(O23*(1+Q23),0),O23*(1+Q23)) -> 25.611574 | S23: N | T23: 21' x (70.08'+24') x 0.333' / 27 | U23: Calculated | V23: High | W23: Slab thickness ASSUMED 4" (no structural). Footprint DIM.
A24: 03-110 | B24: 03 | C24: Concrete | D24: Perimeter grade beam 12" w x 20" below slab - concrete | E24: Monolithic | F24: A101 | G24: Perimeter | H24: Volume | J24: 230.16667 | K24: 1 | L24: 1.6666667 | M24: 0.037037037 | O24: =IF(I24="",1,I24)*IF(J24="",1,J24)*IF(K24="",1,K24)*IF(L24="",1,L24)*IF(M24="",1,M24)-N(N24) -> 14.207819 | P24: CY | Q24: 0.08 | R24: =IF(S24="Y",ROUNDUP(O24*(1+Q24),0),O24*(1+Q24)) -> 15.344444 | S24: N | T24: 2 x (21 + 94.08) LF x 1.0' x 1.667' / 27 | U24: Assumed | V24: Medium | W24: Beam size ASSUMED typical NE LA; engineer to confirm.
A25: 03-120 | B25: 03 | C25: Concrete | D25: Interior grade beams 12" w x 16" below slab - concrete | F25: A101 | G25: 5 transverse + 1 longitudinal | H25: Volume | J25: 187.08333 | K25: 1 | L25: 1.3333333 | M25: 0.037037037 | O25: =IF(I25="",1,I25)*IF(J25="",1,J25)*IF(K25="",1,K25)*IF(L25="",1,L25)*IF(M25="",1,M25)-N(N25) -> 9.2386831 | P25: CY | Q25: 0.08 | R25: =IF(S25="Y",ROUNDUP(O25*(1+Q25),0),O25*(1+Q25)) -> 9.9777778 | S25: N | T25: (5 x 19' + 92.08') x 1.0' x 1.333' / 27 | U25: Assumed | V25: Low | W25: Layout ASSUMED ~20' grid.
A26: 03-130 | B26: 03 | C26: Concrete | D26: Vapor retarder 10 mil poly, lapped & taped | F26: A101 | G26: Under slab | H26: Area | J26: 21 | K26: 94.083333 | O26: =IF(I26="",1,I26)*IF(J26="",1,J26)*IF(K26="",1,K26)*IF(L26="",1,L26)*IF(M26="",1,M26)-N(N26) -> 1975.75 | P26: SF | Q26: 0.15 | R26: =IF(S26="Y",ROUNDUP(O26*(1+Q26),0),O26*(1+Q26)) -> 2272.1125 | S26: N | T26: 21' x 94.08' (+15% laps/beam sides) | U26: Calculated | V26: High
A27: 03-140 | B27: 03 | C27: Concrete | D27: Rebar #5 continuous in grade beams (4 bars) | E27: Grade 60 | F27: A101 | G27: All beams | H27: Length | I27: 4 | J27: 417.25 | O27: =IF(I27="",1,I27)*IF(J27="",1,J27)*IF(K27="",1,K27)*IF(L27="",1,L27)*IF(M27="",1,M27)-N(N27) -> 1669 | P27: LF | Q27: 0.1 | R27: =IF(S27="Y",ROUNDUP(O27*(1+Q27),0),O27*(1+Q27)) -> 1835.9 | S27: N | T27: 4 bars x (230.17 + 187.08) LF | U27: Assumed | V27: Medium
A28: 03-150 | B28: 03 | C28: Concrete | D28: Rebar #3 @ 18" O.C. each way in slab | E28: Grade 60 | F28: A101 | G28: Slab | H28: Length | J28: 21 | K28: 94.083333 | M28: 1.3333333 | O28: =IF(I28="",1,I28)*IF(J28="",1,J28)*IF(K28="",1,K28)*IF(L28="",1,L28)*IF(M28="",1,M28)-N(N28) -> 2634.3333 | P28: LF | Q28: 0.1 | R28: =IF(S28="Y",ROUNDUP(O28*(1+Q28),0),O28*(1+Q28)) -> 2897.7667 | S28: N | T28: 1975.7 SF x (2 / 1.5 ft) LF/SF | U28: Assumed | V28: Medium
A29: 03-160 | B29: 03 | C29: Concrete | D29: Forms, chairs, stakes, ties, edge/expansion material | F29: A101 | G29: Slab | H29: Area | J29: 21 | K29: 94.083333 | O29: =IF(I29="",1,I29)*IF(J29="",1,J29)*IF(K29="",1,K29)*IF(L29="",1,L29)*IF(M29="",1,M29)-N(N29) -> 1975.75 | P29: SF | Q29: 0 | R29: =IF(S29="Y",ROUNDUP(O29*(1+Q29),0),O29*(1+Q29)) -> 1975.75 | S29: N | T29: slab area | U29: Calculated | V29: High
A30: 03-170 | B30: 03 | C30: Concrete | D30: Foundation labor: form, set steel, place & finish (sub) | F30: A101 | G30: Slab | H30: Area | J30: 21 | K30: 94.083333 | O30: =IF(I30="",1,I30)*IF(J30="",1,J30)*IF(K30="",1,K30)*IF(L30="",1,L30)*IF(M30="",1,M30)-N(N30) -> 1975.75 | P30: SF | Q30: 0 | R30: =IF(S30="Y",ROUNDUP(O30*(1+Q30),0),O30*(1+Q30)) -> 1975.75 | S30: N | T30: slab area | U30: Calculated | V30: High
A31: 03-175 | B31: 03 | C31: Concrete | D31: Concrete pump truck | F31: — | G31: Slab pour | H31: Allowance | I31: 1 | O31: =IF(I31="",1,I31)*IF(J31="",1,J31)*IF(K31="",1,K31)*IF(L31="",1,L31)*IF(M31="",1,M31)-N(N31) -> 1 | P31: LS | Q31: 0 | R31: =IF(S31="Y",ROUNDUP(O31*(1+Q31),0),O31*(1+Q31)) -> 1 | S31: N | U31: Allowance | V31: Medium
A32: 03-180 | B32: 03 | C32: Concrete | D32: Finished concrete floors: smooth trowel premium, grind, densifier & sealer | E32: Design notes: Concrete, smooth trowel (all rooms) | F32: Notes / A101 | G32: Conditioned | H32: Area | J32: 21 | K32: 64.166667 | O32: =IF(I32="",1,I32)*IF(J32="",1,J32)*IF(K32="",1,K32)*IF(L32="",1,L32)*IF(M32="",1,M32)-N(N32) -> 1347.5 | P32: SF | Q32: 0 | R32: =IF(S32="Y",ROUNDUP(O32*(1+Q32),0),O32*(1+Q32)) -> 1347.5 | S32: N | T32: 21' x 64.17' | U32: Calculated | V32: High
A33: 03-185 | B33: 03 | C33: Concrete | D33: Porch slab: smooth trowel, slope away, sealer | E33: Design notes | F33: Notes / A101 | G33: Front porch | H33: Area | J33: 21 | K33: 5.9166667 | O33: =IF(I33="",1,I33)*IF(J33="",1,J33)*IF(K33="",1,K33)*IF(L33="",1,L33)*IF(M33="",1,M33)-N(N33) -> 124.25 | P33: SF | Q33: 0 | R33: =IF(S33="Y",ROUNDUP(O33*(1+Q33),0),O33*(1+Q33)) -> 124.25 | S33: N | T33: 21' x 5.92' | U33: Calculated | V33: High
A34: 03-190 | B34: 03 | C34: Concrete | D34: Anchor bolts / sill anchors at exterior walls | F34: A101 | G34: Exterior walls | H34: Count | I34: 46 | O34: =IF(I34="",1,I34)*IF(J34="",1,J34)*IF(K34="",1,K34)*IF(L34="",1,L34)*IF(M34="",1,M34)-N(N34) -> 46 | P34: EA | Q34: 0 | R34: =IF(S34="Y",ROUNDUP(O34*(1+Q34),0),O34*(1+Q34)) -> 46 | S34: N | T34: 182.2 LF / 6' O.C. + 2 per plate piece (~8 pcs) | U34: Calculated | V34: Medium
A35: 03-200 | B35: 03 | C35: Concrete | D35: Saw-cut control joints | F35: A101 | G35: Slab | H35: Length | J35: 120 | O35: =IF(I35="",1,I35)*IF(J35="",1,J35)*IF(K35="",1,K35)*IF(L35="",1,L35)*IF(M35="",1,M35)-N(N35) -> 120 | P35: LF | Q35: 0 | R35: =IF(S35="Y",ROUNDUP(O35*(1+Q35),0),O35*(1+Q35)) -> 120 | S35: N | T35: ~5 joints x 21' + porch | U35: Assumed | V35: Medium
A36: 03-220 | B36: 03 | C36: Concrete | D36: Carport post footings 24"x24"x24" w/ post base | F36: A101 | G36: Carport corners | H36: Count | I36: 2 | O36: =IF(I36="",1,I36)*IF(J36="",1,J36)*IF(K36="",1,K36)*IF(L36="",1,L36)*IF(M36="",1,M36)-N(N36) -> 2 | P36: EA | Q36: 0 | R36: =IF(S36="Y",ROUNDUP(O36*(1+Q36),0),O36*(1+Q36)) -> 2 | S36: N | T36: 2 posts shown | U36: Measured | V36: Medium | W36: Footing size ASSUMED.
A37: 06-100 | B37: 06 | C37: Wood & Rough Carpentry | D37: PT 2x6 bottom/sill plate - exterior walls | F37: A101 | G37: Exterior walls | H37: Length | J37: 182.17 | O37: =IF(I37="",1,I37)*IF(J37="",1,J37)*IF(K37="",1,K37)*IF(L37="",1,L37)*IF(M37="",1,M37)-N(N37) -> 182.17 | P37: LF | Q37: 0.1 | R37: =IF(S37="Y",ROUNDUP(O37*(1+Q37),0),O37*(1+Q37)) -> 200.387 | S37: N | T37: 2 x 70.08 + 2 x 21 | U37: Calculated | V37: High
A38: 06-110 | B38: 06 | C38: Wood & Rough Carpentry | D38: 2x6 double top plate - exterior walls | F38: A101 | G38: Exterior walls | H38: Length | I38: 2 | J38: 182.17 | O38: =IF(I38="",1,I38)*IF(J38="",1,J38)*IF(K38="",1,K38)*IF(L38="",1,L38)*IF(M38="",1,M38)-N(N38) -> 364.34 | P38: LF | Q38: 0.1 | R38: =IF(S38="Y",ROUNDUP(O38*(1+Q38),0),O38*(1+Q38)) -> 400.774 | S38: N | T38: 2 plates x 182.17 LF | U38: Calculated | V38: High
A39: 06-120 | B39: 06 | C39: Wood & Rough Carpentry | D39: 2x6 x 104-5/8" studs @ 24" O.C. - exterior walls | E39: Design notes: 2x6 ext walls @ 24" O.C. | F39: Notes / A101 | G39: Exterior walls | H39: Count | I39: =ROUNDUP(182.17/2,0)+4*3+10*2+14*4+28 -> 208 | O39: =IF(I39="",1,I39)*IF(J39="",1,J39)*IF(K39="",1,K39)*IF(L39="",1,L39)*IF(M39="",1,M39)-N(N39) -> 208 | P39: EA | Q39: 0.1 | R39: =IF(S39="Y",ROUNDUP(O39*(1+Q39),0),O39*(1+Q39)) -> 229 | S39: Y | T39: LF/2 + corners 4x3 + partition T's 10x2 + 14 openings x4 (king+jack) + ~28 cripples | U39: Calculated | V39: Medium
A40: 06-130 | B40: 06 | C40: Wood & Rough Carpentry | D40: 2x10 header stock, 2-ply - exterior openings | F40: A701 | G40: Exterior openings | H40: Length | I40: 2 | J40: 69 | O40: =IF(I40="",1,I40)*IF(J40="",1,J40)*IF(K40="",1,K40)*IF(L40="",1,L40)*IF(M40="",1,M40)-N(N40) -> 138 | P40: LF | Q40: 0.1 | R40: =IF(S40="Y",ROUNDUP(O40*(1+Q40),0),O40*(1+Q40)) -> 151.8 | S40: N | T40: 2 ply x Σ(opening width + 6"); D windows ganged on one 9.5' header | U40: Calculated | V40: Medium | W40: Header sizes ASSUMED (no structural).
...

Sheet Cost Database
A1: Cost ID | B1: Cost Code | C1: Description | D1: Unit | E1: Material $/unit | F1: Labor $/unit | G1: Sub / Equip / Other $/unit | H1: Total $/unit | I1: Source | J1: Market | K1: Price Date | L1: Notes
A2: 01-100 | B2: 01 | C2: Building permit & plan review | D2: LS | E2: 0 | F2: 0 | G2: 2600 | H2: =E2+F2+G2 -> 2600 | I2: Estimator budget unit cost, NE Louisiana (Monroe/Ouachita) Q4-2026 - not a quote; verify with local supplier/sub | J2: Monroe / West Monroe / Ouachita Parish, LA | K2: 2026-10-15 | L2: Material pre-tax
A3: 01-105 | B3: 01 | C3: Engineering: foundation design, carport/porch beams, truss review | D3: LS | E3: 0 | F3: 0 | G3: 1800 | H3: =E3+F3+G3 -> 1800 | I3: Estimator budget unit cost, NE Louisiana (Monroe/Ouachita) Q4-2026 - not a quote; verify with local supplier/sub | J3: Monroe / West Monroe / Ouachita Parish, LA | K3: 2026-10-15 | L3: Material pre-tax
A4: 01-106 | B4: 01 | C4: Geotechnical investigation (borings, PI, slab recommendations) | D4: LS | E4: 0 | F4: 0 | G4: 1900 | H4: =E4+F4+G4 -> 1900 | I4: Estimator budget unit cost, NE Louisiana (Monroe/Ouachita) Q4-2026 - not a quote; verify with local supplier/sub | J4: Monroe / West Monroe / Ouachita Parish, LA | K4: 2026-10-15 | L4: Material pre-tax
A5: 01-110 | B5: 01 | C5: Survey: boundary, staking, form-board, final as-built | D5: LS | E5: 0 | F5: 0 | G5: 1850 | H5: =E5+F5+G5 -> 1850 | I5: Estimator budget unit cost, NE Louisiana (Monroe/Ouachita) Q4-2026 - not a quote; verify with local supplier/sub | J5: Monroe / West Monroe / Ouachita Parish, LA | K5: 2026-10-15 | L5: Material pre-tax
A6: 01-120 | B6: 01 | C6: Temporary power pole, connection & usage | D6: LS | E6: 250 | F6: 0 | G6: 900 | H6: =E6+F6+G6 -> 1150 | I6: Estimator budget unit cost, NE Louisiana (Monroe/Ouachita) Q4-2026 - not a quote; verify with local supplier/sub | J6: Monroe / West Monroe / Ouachita Parish, LA | K6: 2026-10-15 | L6: Material pre-tax
A7: 01-125 | B7: 01 | C7: Temporary water & usage | D7: LS | E7: 0 | F7: 0 | G7: 300 | H7: =E7+F7+G7 -> 300 | I7: Estimator budget unit cost, NE Louisiana (Monroe/Ouachita) Q4-2026 - not a quote; verify with local supplier/sub | J7: Monroe / West Monroe / Ouachita Parish, LA | K7: 2026-10-15 | L7: Material pre-tax
A8: 01-130 | B8: 01 | C8: Portable toilet | D8: MO | E8: 0 | F8: 0 | G8: 165 | H8: =E8+F8+G8 -> 165 | I8: Estimator budget unit cost, NE Louisiana (Monroe/Ouachita) Q4-2026 - not a quote; verify with local supplier/sub | J8: Monroe / West Monroe / Ouachita Parish, LA | K8: 2026-10-15 | L8: Material pre-tax
A9: 01-140 | B9: 01 | C9: Dumpster, 20 CY, haul & dump | D9: EA | E9: 0 | F9: 0 | G9: 485 | H9: =E9+F9+G9 -> 485 | I9: Estimator budget unit cost, NE Louisiana (Monroe/Ouachita) Q4-2026 - not a quote; verify with local supplier/sub | J9: Monroe / West Monroe / Ouachita Parish, LA | K9: 2026-10-15 | L9: Material pre-tax
A10: 01-150 | B10: 01 | C10: Builder's risk insurance | D10: LS | E10: 0 | F10: 0 | G10: 1250 | H10: =E10+F10+G10 -> 1250 | I10: Estimator budget unit cost, NE Louisiana (Monroe/Ouachita) Q4-2026 - not a quote; verify with local supplier/sub | J10: Monroe / West Monroe / Ouachita Parish, LA | K10: 2026-10-15 | L10: Material pre-tax
A11: 01-160 | B11: 01 | C11: Site supervision (part-time superintendent) | D11: WK | E11: 0 | F11: 650 | G11: 0 | H11: =E11+F11+G11 -> 650 | I11: Estimator budget unit cost, NE Louisiana (Monroe/Ouachita) Q4-2026 - not a quote; verify with local supplier/sub | J11: Monroe / West Monroe / Ouachita Parish, LA | K11: 2026-10-15 | L11: Material pre-tax
A12: 01-170 | B12: 01 | C12: Final construction clean incl. windows | D12: SF | E12: 0 | F12: 0 | G12: 0.35 | H12: =E12+F12+G12 -> 0.35 | I12: Estimator budget unit cost, NE Louisiana (Monroe/Ouachita) Q4-2026 - not a quote; verify with local supplier/sub | J12: Monroe / West Monroe / Ouachita Parish, LA | K12: 2026-10-15 | L12: Material pre-tax
A13: 01-175 | B13: 01 | C13: Periodic jobsite cleanup | D13: LS | E13: 0 | F13: 900 | G13: 0 | H13: =E13+F13+G13 -> 900 | I13: Estimator budget unit cost, NE Louisiana (Monroe/Ouachita) Q4-2026 - not a quote; verify with local supplier/sub | J13: Monroe / West Monroe / Ouachita Parish, LA | K13: 2026-10-15 | L13: Material pre-tax
... A173: 33-140 | B173: 33 | C173: Utility company service/connection charges | D173: LS | E173: 0 | F173: 0 | G173: 800 | H173: =E173+F173+G173 -> 800 | I173: Estimator budget unit cost, NE Louisiana (Monroe/Ouachita) Q4-2026 - not a quote; verify with local supplier/sub | J173: Monroe / West Monroe / Ouachita Parish, LA | K173: 2026-10-15 | L173: Material pre-tax

Sheet Estimate Detail
A1: Line | B1: Cost Code | C1: Division | D1: Description | E1: Takeoff ID | F1: Qty (gross) | G1: Unit | H1: Cost ID | I1: Material $/u | J1: Labor $/u | K1: Sub/Equip $/u | L1: Material $ | M1: Labor $ | N1: Sub/Equip $ | O1: Line Total $ | P1: Basis | Q1: Confidence | R1: $ / Cond. SF
A2: 1 | B2: 01 | C2: General Requirements | D2: Building permit & plan review | E2: 01-100 | F2: =INDEX('Takeoff Detail'!$R:$R,MATCH(E2,'Takeoff Detail'!$A:$A,0)) -> 1 | G2: =INDEX('Takeoff Detail'!$P:$P,MATCH(E2,'Takeoff Detail'!$A:$A,0)) -> LS | H2: 01-100 | I2: =INDEX('Cost Database'!$E:$E,MATCH(H2,'Cost Database'!$A:$A,0)) -> 0 | J2: =INDEX('Cost Database'!$F:$F,MATCH(H2,'Cost Database'!$A:$A,0)) -> 0 | K2: =INDEX('Cost Database'!$G:$G,MATCH(H2,'Cost Database'!$A:$A,0)) -> 2600 | L2: =F2*I2 -> 0 | M2: =F2*J2 -> 0 | N2: =F2*K2 -> 2600 | O2: =L2+M2+N2 -> 2600 | P2: =INDEX('Takeoff Detail'!$U:$U,MATCH(E2,'Takeoff Detail'!$A:$A,0)) -> Allowance | Q2: =INDEX('Takeoff Detail'!$V:$V,MATCH(E2,'Takeoff Detail'!$A:$A,0)) -> Medium | R2: =O2/Summary!$C$4 -> 1.9230769
A3: 2 | B3: 01 | C3: General Requirements | D3: Engineering: foundation design, carport/porch beams, truss review | E3: 01-105 | F3: =INDEX('Takeoff Detail'!$R:$R,MATCH(E3,'Takeoff Detail'!$A:$A,0)) -> 1 | G3: =INDEX('Takeoff Detail'!$P:$P,MATCH(E3,'Takeoff Detail'!$A:$A,0)) -> LS | H3: 01-105 | I3: =INDEX('Cost Database'!$E:$E,MATCH(H3,'Cost Database'!$A:$A,0)) -> 0 | J3: =INDEX('Cost Database'!$F:$F,MATCH(H3,'Cost Database'!$A:$A,0)) -> 0 | K3: =INDEX('Cost Database'!$G:$G,MATCH(H3,'Cost Database'!$A:$A,0)) -> 1800 | L3: =F3*I3 -> 0 | M3: =F3*J3 -> 0 | N3: =F3*K3 -> 1800 | O3: =L3+M3+N3 -> 1800 | P3: =INDEX('Takeoff Detail'!$U:$U,MATCH(E3,'Takeoff Detail'!$A:$A,0)) -> Allowance | Q3: =INDEX('Takeoff Detail'!$V:$V,MATCH(E3,'Takeoff Detail'!$A:$A,0)) -> Medium | R3: =O3/Summary!$C$4 -> 1.3313609
A4: 3 | B4: 01 | C4: General Requirements | D4: Geotechnical investigation (borings, PI, slab recommendations) | E4: 01-106 | F4: =INDEX('Takeoff Detail'!$R:$R,MATCH(E4,'Takeoff Detail'!$A:$A,0)) -> 1 | G4: =INDEX('Takeoff Detail'!$P:$P,MATCH(E4,'Takeoff Detail'!$A:$A,0)) -> LS | H4: 01-106 | I4: =INDEX('Cost Database'!$E:$E,MATCH(H4,'Cost Database'!$A:$A,0)) -> 0 | J4: =INDEX('Cost Database'!$F:$F,MATCH(H4,'Cost Database'!$A:$A,0)) -> 0 | K4: =INDEX('Cost Database'!$G:$G,MATCH(H4,'Cost Database'!$A:$A,0)) -> 1900 | L4: =F4*I4 -> 0 | M4: =F4*J4 -> 0 | N4: =F4*K4 -> 1900 | O4: =L4+M4+N4 -> 1900 | P4: =INDEX('Takeoff Detail'!$U:$U,MATCH(E4,'Takeoff Detail'!$A:$A,0)) -> Allowance | Q4: =INDEX('Takeoff Detail'!$V:$V,MATCH(E4,'Takeoff Detail'!$A:$A,0)) -> Medium | R4: =O4/Summary!$C$4 -> 1.4053254
A5: 4 | B5: 01 | C5: General Requirements | D5: Survey: boundary, staking, form-board, final as-built | E5: 01-110 | F5: =INDEX('Takeoff Detail'!$R:$R,MATCH(E5,'Takeoff Detail'!$A:$A,0)) -> 1 | G5: =INDEX('Takeoff Detail'!$P:$P,MATCH(E5,'Takeoff Detail'!$A:$A,0)) -> LS | H5: 01-110 | I5: =INDEX('Cost Database'!$E:$E,MATCH(H5,'Cost Database'!$A:$A,0)) -> 0 | J5: =INDEX('Cost Database'!$F:$F,MATCH(H5,'Cost Database'!$A:$A,0)) -> 0 | K5: =INDEX('Cost Database'!$G:$G,MATCH(H5,'Cost Database'!$A:$A,0)) -> 1850 | L5: =F5*I5 -> 0 | M5: =F5*J5 -> 0 | N5: =F5*K5 -> 1850 | O5: =L5+M5+N5 -> 1850 | P5: =INDEX('Takeoff Detail'!$U:$U,MATCH(E5,'Takeoff Detail'!$A:$A,0)) -> Allowance | Q5: =INDEX('Takeoff Detail'!$V:$V,MATCH(E5,'Takeoff Detail'!$A:$A,0)) -> Medium | R5: =O5/Summary!$C$4 -> 1.3683432
A6: 5 | B6: 01 | C6: General Requirements | D6: Temporary power pole, connection & usage | E6: 01-120 | F6: =INDEX('Takeoff Detail'!$R:$R,MATCH(E6,'Takeoff Detail'!$A:$A,0)) -> 1 | G6: =INDEX('Takeoff Detail'!$P:$P,MATCH(E6,'Takeoff Detail'!$A:$A,0)) -> LS | H6: 01-120 | I6: =INDEX('Cost Database'!$E:$E,MATCH(H6,'Cost Database'!$A:$A,0)) -> 250 | J6: =INDEX('Cost Database'!$F:$F,MATCH(H6,'Cost Database'!$A:$A,0)) -> 0 | K6: =INDEX('Cost Database'!$G:$G,MATCH(H6,'Cost Database'!$A:$A,0)) -> 900 | L6: =F6*I6 -> 250 | M6: =F6*J6 -> 0 | N6: =F6*K6 -> 900 | O6: =L6+M6+N6 -> 1150 | P6: =INDEX('Takeoff Detail'!$U:$U,MATCH(E6,'Takeoff Detail'!$A:$A,0)) -> Allowance | Q6: =INDEX('Takeoff Detail'!$V:$V,MATCH(E6,'Takeoff Detail'!$A:$A,0)) -> Medium | R6: =O6/Summary!$C$4 -> 0.85059172
A7: 6 | B7: 01 | C7: General Requirements | D7: Temporary water & usage | E7: 01-125 | F7: =INDEX('Takeoff Detail'!$R:$R,MATCH(E7,'Takeoff Detail'!$A:$A,0)) -> 1 | G7: =INDEX('Takeoff Detail'!$P:$P,MATCH(E7,'Takeoff Detail'!$A:$A,0)) -> LS | H7: 01-125 | I7: =INDEX('Cost Database'!$E:$E,MATCH(H7,'Cost Database'!$A:$A,0)) -> 0 | J7: =INDEX('Cost Database'!$F:$F,MATCH(H7,'Cost Database'!$A:$A,0)) -> 0 | K7: =INDEX('Cost Database'!$G:$G,MATCH(H7,'Cost Database'!$A:$A,0)) -> 300 | L7: =F7*I7 -> 0 | M7: =F7*J7 -> 0 | N7: =F7*K7 -> 300 | O7: =L7+M7+N7 -> 300 | P7: =INDEX('Takeoff Detail'!$U:$U,MATCH(E7,'Takeoff Detail'!$A:$A,0)) -> Allowance | Q7: =INDEX('Takeoff Detail'!$V:$V,MATCH(E7,'Takeoff Detail'!$A:$A,0)) -> Medium | R7: =O7/Summary!$C$4 -> 0.22189349
A8: 7 | B8: 01 | C8: General Requirements | D8: Portable toilet | E8: 01-130 | F8: =INDEX('Takeoff Detail'!$R:$R,MATCH(E8,'Takeoff Detail'!$A:$A,0)) -> 5 | G8: =INDEX('Takeoff Detail'!$P:$P,MATCH(E8,'Takeoff Detail'!$A:$A,0)) -> MO | H8: 01-130 | I8: =INDEX('Cost Database'!$E:$E,MATCH(H8,'Cost Database'!$A:$A,0)) -> 0 | J8: =INDEX('Cost Database'!$F:$F,MATCH(H8,'Cost Database'!$A:$A,0)) -> 0 | K8: =INDEX('Cost Database'!$G:$G,MATCH(H8,'Cost Database'!$A:$A,0)) -> 165 | L8: =F8*I8 -> 0 | M8: =F8*J8 -> 0 | N8: =F8*K8 -> 825 | O8: =L8+M8+N8 -> 825 | P8: =INDEX('Takeoff Detail'!$U:$U,MATCH(E8,'Takeoff Detail'!$A:$A,0)) -> Assumed | Q8: =INDEX('Takeoff Detail'!$V:$V,MATCH(E8,'Takeoff Detail'!$A:$A,0)) -> Medium | R8: =O8/Summary!$C$4 -> 0.6102071
A9: 8 | B9: 01 | C9: General Requirements | D9: Dumpster, 20 CY, haul & dump | E9: 01-140 | F9: =INDEX('Takeoff Detail'!$R:$R,MATCH(E9,'Takeoff Detail'!$A:$A,0)) -> 5 | G9: =INDEX('Takeoff Detail'!$P:$P,MATCH(E9,'Takeoff Detail'!$A:$A,0)) -> EA | H9: 01-140 | I9: =INDEX('Cost Database'!$E:$E,MATCH(H9,'Cost Database'!$A:$A,0)) -> 0 | J9: =INDEX('Cost Database'!$F:$F,MATCH(H9,'Cost Database'!$A:$A,0)) -> 0 | K9: =INDEX('Cost Database'!$G:$G,MATCH(H9,'Cost Database'!$A:$A,0)) -> 485 | L9: =F9*I9 -> 0 | M9: =F9*J9 -> 0 | N9: =F9*K9 -> 2425 | O9: =L9+M9+N9 -> 2425 | P9: =INDEX('Takeoff Detail'!$U:$U,MATCH(E9,'Takeoff Detail'!$A:$A,0)) -> Assumed | Q9: =INDEX('Takeoff Detail'!$V:$V,MATCH(E9,'Takeoff Detail'!$A:$A,0)) -> Medium | R9: =O9/Summary!$C$4 -> 1.7936391
A10: 9 | B10: 01 | C10: General Requirements | D10: Builder's risk insurance | E10: 01-150 | F10: =INDEX('Takeoff Detail'!$R:$R,MATCH(E10,'Takeoff Detail'!$A:$A,0)) -> 1 | G10: =INDEX('Takeoff Detail'!$P:$P,MATCH(E10,'Takeoff Detail'!$A:$A,0)) -> LS | H10: 01-150 | I10: =INDEX('Cost Database'!$E:$E,MATCH(H10,'Cost Database'!$A:$A,0)) -> 0 | J10: =INDEX('Cost Database'!$F:$F,MATCH(H10,'Cost Database'!$A:$A,0)) -> 0 | K10: =INDEX('Cost Database'!$G:$G,MATCH(H10,'Cost Database'!$A:$A,0)) -> 1250 | L10: =F10*I10 -> 0 | M10: =F10*J10 -> 0 | N10: =F10*K10 -> 1250 | O10: =L10+M10+N10 -> 1250 | P10: =INDEX('Takeoff Detail'!$U:$U,MATCH(E10,'Takeoff Detail'!$A:$A,0)) -> Allowance | Q10: =INDEX('Takeoff Detail'!$V:$V,MATCH(E10,'Takeoff Detail'!$A:$A,0)) -> Medium | R10: =O10/Summary!$C$4 -> 0.92455621
A11: 10 | B11: 01 | C11: General Requirements | D11: Site supervision (part-time superintendent) | E11: 01-160 | F11: =INDEX('Takeoff Detail'!$R:$R,MATCH(E11,'Takeoff Detail'!$A:$A,0)) -> 20 | G11: =INDEX('Takeoff Detail'!$P:$P,MATCH(E11,'Takeoff Detail'!$A:$A,0)) -> WK | H11: 01-160 | I11: =INDEX('Cost Database'!$E:$E,MATCH(H11,'Cost Database'!$A:$A,0)) -> 0 | J11: =INDEX('Cost Database'!$F:$F,MATCH(H11,'Cost Database'!$A:$A,0)) -> 650 | K11: =INDEX('Cost Database'!$G:$G,MATCH(H11,'Cost Database'!$A:$A,0)) -> 0 | L11: =F11*I11 -> 0 | M11: =F11*J11 -> 13000 | N11: =F11*K11 -> 0 | O11: =L11+M11+N11 -> 13000 | P11: =INDEX('Takeoff Detail'!$U:$U,MATCH(E11,'Takeoff Detail'!$A:$A,0)) -> Assumed | Q11: =INDEX('Takeoff Detail'!$V:$V,MATCH(E11,'Takeoff Detail'!$A:$A,0)) -> Medium | R11: =O11/Summary!$C$4 -> 9.6153846
A12: 11 | B12: 01 | C12: General Requirements | D12: Final construction clean incl. windows | E12: 01-170 | F12: =INDEX('Takeoff Detail'!$R:$R,MATCH(E12,'Takeoff Detail'!$A:$A,0)) -> 1975.75 | G12: =INDEX('Takeoff Detail'!$P:$P,MATCH(E12,'Takeoff Detail'!$A:$A,0)) -> SF | H12: 01-170 | I12: =INDEX('Cost Database'!$E:$E,MATCH(H12,'Cost Database'!$A:$A,0)) -> 0 | J12: =INDEX('Cost Database'!$F:$F,MATCH(H12,'Cost Database'!$A:$A,0)) -> 0 | K12: =INDEX('Cost Database'!$G:$G,MATCH(H12,'Cost Database'!$A:$A,0)) -> 0.35 | L12: =F12*I12 -> 0 | M12: =F12*J12 -> 0 | N12: =F12*K12 -> 691.5125 | O12: =L12+M12+N12 -> 691.5125 | P12: =INDEX('Takeoff Detail'!$U:$U,MATCH(E12,'Takeoff Detail'!$A:$A,0)) -> Calculated | Q12: =INDEX('Takeoff Detail'!$V:$V,MATCH(E12,'Takeoff Detail'!$A:$A,0)) -> High | R12: =O12/Summary!$C$4 -> 0.51147374
A13: 12 | B13: 01 | C13: General Requirements | D13: Periodic jobsite cleanup | E13: 01-175 | F13: =INDEX('Takeoff Detail'!$R:$R,MATCH(E13,'Takeoff Detail'!$A:$A,0)) -> 1 | G13: =INDEX('Takeoff Detail'!$P:$P,MATCH(E13,'Takeoff Detail'!$A:$A,0)) -> LS | H13: 01-175 | I13: =INDEX('Cost Database'!$E:$E,MATCH(H13,'Cost Database'!$A:$A,0)) -> 0 | J13: =INDEX('Cost Database'!$F:$F,MATCH(H13,'Cost Database'!$A:$A,0)) -> 900 | K13: =INDEX('Cost Database'!$G:$G,MATCH(H13,'Cost Database'!$A:$A,0)) -> 0 | L13: =F13*I13 -> 0 | M13: =F13*J13 -> 900 | N13: =F13*K13 -> 0 | O13: =L13+M13+N13 -> 900 | P13: =INDEX('Takeoff Detail'!$U:$U,MATCH(E13,'Takeoff Detail'!$A:$A,0)) -> Allowance | Q13: =INDEX('Takeoff Detail'!$V:$V,MATCH(E13,'Takeoff Detail'!$A:$A,0)) -> Medium | R13: =O13/Summary!$C$4 -> 0.66568047
... A173: 172 | B173: 33 | C173: Utilities | D173: Utility company service/connection charges | E173: 33-140 | F173: =INDEX('Takeoff Detail'!$R:$R,MATCH(E173,'Takeoff Detail'!$A:$A,0)) -> 1 | G173: =INDEX('Takeoff Detail'!$P:$P,MATCH(E173,'Takeoff Detail'!$A:$A,0)) -> LS | H173: 33-140 | I173: =INDEX('Cost Database'!$E:$E,MATCH(H173,'Cost Database'!$A:$A,0)) -> 0 | J173: =INDEX('Cost Database'!$F:$F,MATCH(H173,'Cost Database'!$A:$A,0)) -> 0 | K173: =INDEX('Cost Database'!$G:$G,MATCH(H173,'Cost Database'!$A:$A,0)) -> 800 | L173: =F173*I173 -> 0 | M173: =F173*J173 -> 0 | N173: =F173*K173 -> 800 | O173: =L173+M173+N173 -> 800 | P173: =INDEX('Takeoff Detail'!$U:$U,MATCH(E173,'Takeoff Detail'!$A:$A,0)) -> Allowance | Q173: =INDEX('Takeoff Detail'!$V:$V,MATCH(E173,'Takeoff Detail'!$A:$A,0)) -> Low | R173: =O173/Summary!$C$4 -> 0.59171598
D174: TOTAL DIRECT COST | L174: =SUBTOTAL(109,L2:L173) -> 112469.36 | M174: =SUBTOTAL(109,M2:M173) -> 100225.28 | N174: =SUBTOTAL(109,N2:N173) -> 42988.058 | O174: =SUBTOTAL(109,O2:O173) -> 255682.69

Sheet Reconciliation
A1: Check | B1: Takeoff / Workbook Qty | C1: Model / Reference Qty | D1: Unit | E1: Variance | F1: Variance % | G1: Reason / Explanation | H1: Review Status
A2: Conditioned area vs. design notes (1,352 gsf) | B2: ='Takeoff Detail'!O14 -> 1347.5 | C2: 1352 | D2: SF | E2: =B2-C2 -> -4.5 | F2: =IF(C2=0,"",(B2-C2)/C2) -> -0.0033284024 | G2: Takeoff uses dimensioned 21'-0" x 64'-2". Notes area likely measured to outside of sheathing/siding. Within tolerance. | H2: OK
A3: Porch area vs. design notes (117 gsf) | B3: ='Takeoff Detail'!O33 -> 124.25 | C3: 117 | D3: SF | E3: =B3-C3 -> 7.25 | F3: =IF(C3=0,"",(B3-C3)/C3) -> 0.061965812 | G3: Takeoff = slab under porch incl. side-wall footprint (21' x 5'-11"); notes = clear area between porch walls (~19.8' x 5.92'). Not an error. | H3: Explained
A4: Covered parking vs. design notes (504 gsf) | B4: ='Takeoff Detail'!J77*'Takeoff Detail'!K77 -> 504 | C4: 504 | D4: SF | E4: =B4-C4 -> 0 | F4: =IF(C4=0,"",(B4-C4)/C4) -> 0 | G4: 21'-0" x 24'-0" dimensioned. | H4: OK
A5: Total under roof vs. design notes (1,973 gsf) | B5: ='Takeoff Detail'!O12 -> 1975.75 | C5: 1973 | D5: SF | E5: =B5-C5 -> 2.75 | F5: =IF(C5=0,"",(B5-C5)/C5) -> 0.0013938165 | G5: Dimensions sum to 70'-1" vs 70'-0" overall (1" chain rounding) - 0.1%. | H5: OK
A6: Slab footprint: takeoff vs. model | B6: ='Takeoff Detail'!O29 -> 1975.75 | C6: 1975.75 | D6: SF | E6: =B6-C6 -> 0 | F6: =IF(C6=0,"",(B6-C6)/C6) -> 0 | G6: Same dimension source. | H6: OK
A7: Exterior 2x6 wall length: takeoff vs. model | B7: ='Takeoff Detail'!O37 -> 182.17 | C7: 182.17 | D7: LF | E7: =B7-C7 -> 0 | F7: =IF(C7=0,"",(B7-C7)/C7) -> 0 | G7: Includes porch side walls (W/E walls run 70'-1"). | H7: OK
A8: Interior partition length: takeoff vs. model | B8: ='Takeoff Detail'!O41 -> 138.56 | C8: 138.56 | D8: LF | E8: =B8-C8 -> 0 | F8: =IF(C8=0,"",(B8-C8)/C8) -> 0 | G8: Both from scaled partition coordinates (calibrated 18.81 px/ft). Partition locations are not dimensioned on A101 - scaled tolerance about +/-3". | H8: Review
A9: Window count: takeoff vs. model vs. A701 schedule (11) | B9: ='Takeoff Detail'!I87+'Takeoff Detail'!I88+'Takeoff Detail'!I89+'Takeoff Detail'!I90 -> 11 | C9: 11 | D9: EA | E9: =B9-C9 -> 0 | F9: =IF(C9=0,"",(B9-C9)/C9) -> 0 | G9: Schedule 11 = plan tags 11 = elevations 11 (A x5 west, B x2 east, C x1 rear, D x3 front). | H9: OK
A10: Exterior doors: takeoff vs. model (A701 01, 09, 10) | B10: ='Takeoff Detail'!I91+'Takeoff Detail'!I92+'Takeoff Detail'!I93 -> 3 | C10: 3 | D10: EA | E10: =B10-C10 -> 0 | F10: =IF(C10=0,"",(B10-C10)/C10) -> 0 | H10: OK
A11: Interior doors: takeoff vs. model (A701 02-08) | B11: ='Takeoff Detail'!I94+'Takeoff Detail'!I95 -> 7 | C11: 7 | D11: EA | E11: =B11-C11 -> 0 | F11: =IF(C11=0,"",(B11-C11)/C11) -> 0 | H11: OK
A12: Roof area (sloped): takeoff vs. model | B12: ='Takeoff Detail'!O70*100 -> 2470.6783 | C12: 2470.76 | D12: SF | E12: =B12-C12 -> -0.081738 | F12: =IF(C12=0,"",(B12-C12)/C12) -> -3.3082129e-05 | G12: Both include ASSUMED 12" eave & rake overhangs. | H12: OK
A13: Truss count: takeoff vs. model | B13: ='Takeoff Detail'!I46+'Takeoff Detail'!I47+'Takeoff Detail'!I48 -> 25 | C13: 25 | D13: EA | E13: =B13-C13 -> 0 | F13: =IF(C13=0,"",(B13-C13)/C13) -> 0 | G13: 48" O.C. per design notes (see RFI-06). | H13: OK
A14: Light fixtures (cans + pendants + fans): takeoff vs. model RCP count | B14: ='Takeoff Detail'!I153+'Takeoff Detail'!I154+'Takeoff Detail'!I155 -> 28 | C14: 28 | D14: EA | E14: =B14-C14 -> 0 | F14: =IF(C14=0,"",(B14-C14)/C14) -> 0 | G14: Exterior soffit/wall lights (26-330) are counted separately and are not on the RCP. | H14: OK
A15: Overall length: dimension chain vs. overall dim 70'-0" | B15: 70.083 | C15: 70 | D15: FT | E15: =B15-C15 -> 0.083 | F15: =IF(C15=0,"",(B15-C15)/C15) -> 0.0011857143 | G15: 6'-10" + 13'-5" + 9'-10" + 11'-2" + 22'-11" + 5'-11" = 70'-1". 1" discrepancy on A101 - used the chain. | H15: Explained
A16: Plan calibration: 21'-0" vs. vertical 70'-0" (px/ft) | B16: 18.81 | C16: 18.74 | D16: px/ft | E16: =B16-C16 -> 0.07 | F16: =IF(C16=0,"",(B16-C16)/C16) -> 0.0037353255 | G16: Horizontal vs. vertical scale agreement 0.4% - scan/plot distortion negligible. | H16: OK
